<?xml version="1.0"?>
<robot name="pos_robot">

  <!-- ============================================================
       BASE
       ============================================================ -->
  <link name="base_link">
    <visual>
      <geometry><box size="0.5 0.4 0.15"/></geometry>
      <material name="blue"><color rgba="0.1 0.3 0.9 1"/></material>
    </visual>
    <collision>
      <geometry><box size="0.5 0.4 0.15"/></geometry>
    </collision>
    <inertial>
      <mass value="5.0"/>
      <inertia ixx="0.1" ixy="0" ixz="0" iyy="0.1" iyz="0" izz="0.1"/>
    </inertial>
  </link>

  <!-- ============================================================
       DRIVE WHEELS
       Wheel separation = 0.43 m (matches DiffDrive plugin below)
       Wheel radius     = 0.05 m
       ============================================================ -->
  <link name="left_wheel">
    <visual>
      <origin rpy="1.5708 0 0"/>
      <geometry><cylinder radius="0.05" length="0.03"/></geometry>
      <material name="black"><color rgba="0.1 0.1 0.1 1"/></material>
    </visual>
    <collision>
      <origin rpy="1.5708 0 0"/>
      <geometry><cylinder radius="0.05" length="0.03"/></geometry>
    </collision>
    <inertial>
      <mass value="0.2"/>
      <inertia ixx="0.001" ixy="0" ixz="0" iyy="0.001" iyz="0" izz="0.001"/>
    </inertial>
  </link>
  <joint name="left_wheel_joint" type="continuous">
    <parent link="base_link"/>
    <child link="left_wheel"/>
    <origin xyz="0 0.215 -0.025" rpy="0 0 0"/>
    <axis xyz="0 1 0"/>
  </joint>

  <link name="right_wheel">
    <visual>
      <origin rpy="1.5708 0 0"/>
      <geometry><cylinder radius="0.05" length="0.03"/></geometry>
      <material name="black"><color rgba="0.1 0.1 0.1 1"/></material>
    </visual>
    <collision>
      <origin rpy="1.5708 0 0"/>
      <geometry><cylinder radius="0.05" length="0.03"/></geometry>
    </collision>
    <inertial>
      <mass value="0.2"/>
      <inertia ixx="0.001" ixy="0" ixz="0" iyy="0.001" iyz="0" izz="0.001"/>
    </inertial>
  </link>
  <joint name="right_wheel_joint" type="continuous">
    <parent link="base_link"/>
    <child link="right_wheel"/>
    <origin xyz="0 -0.215 -0.025" rpy="0 0 0"/>
    <axis xyz="0 1 0"/>
  </joint>

  <!-- ============================================================
       CASTER (front, fixed sphere — slides on ground)
       ============================================================ -->
  <link name="caster">
    <visual>
      <geometry><sphere radius="0.025"/></geometry>
      <material name="grey"><color rgba="0.5 0.5 0.5 1"/></material>
    </visual>
    <collision>
      <geometry><sphere radius="0.025"/></geometry>
    </collision>
    <inertial>
      <mass value="0.05"/>
      <inertia ixx="0.0001" ixy="0" ixz="0" iyy="0.0001" iyz="0" izz="0.0001"/>
    </inertial>
  </link>
  <joint name="caster_joint" type="fixed">
    <parent link="base_link"/>
    <child link="caster"/>
    <origin xyz="0.20 0 -0.05" rpy="0 0 0"/>
  </joint>

  <!-- ============================================================
       ONBOARD TRAY (the "shelf attached to the robot")
       ============================================================ -->
  <link name="tray_link">
    <visual>
      <geometry><box size="0.45 0.35 0.01"/></geometry>
      <material name="silver"><color rgba="0.8 0.8 0.85 1"/></material>
    </visual>
    <collision>
      <geometry><box size="0.45 0.35 0.01"/></geometry>
    </collision>
    <inertial>
      <mass value="0.3"/>
      <inertia ixx="0.005" ixy="0" ixz="0" iyy="0.005" iyz="0" izz="0.005"/>
    </inertial>
  </link>
  <joint name="tray_joint" type="fixed">
    <parent link="base_link"/>
    <child link="tray_link"/>
    <origin xyz="0 0 0.08" rpy="0 0 0"/>
  </joint>

  <!-- ============================================================
       COSMETIC ARM (non-functional in v1; replaced in v2)
       A column at the back of the base with a horizontal segment.
       Purely visual — there are no movable joints here yet.
       ============================================================ -->
  <link name="arm_column">
    <visual>
      <geometry><cylinder radius="0.03" length="0.4"/></geometry>
      <material name="grey"><color rgba="0.5 0.5 0.5 1"/></material>
    </visual>
    <collision>
      <geometry><cylinder radius="0.03" length="0.4"/></geometry>
    </collision>
    <inertial>
      <mass value="0.5"/>
      <inertia ixx="0.005" ixy="0" ixz="0" iyy="0.005" iyz="0" izz="0.005"/>
    </inertial>
  </link>
  <joint name="arm_column_joint" type="fixed">
    <parent link="base_link"/>
    <child link="arm_column"/>
    <origin xyz="-0.2 0 0.285" rpy="0 0 0"/>
  </joint>

  <link name="arm_segment">
    <visual>
      <origin xyz="0.15 0 0"/>
      <geometry><box size="0.3 0.04 0.04"/></geometry>
      <material name="grey"><color rgba="0.5 0.5 0.5 1"/></material>
    </visual>
    <collision>
      <origin xyz="0.15 0 0"/>
      <geometry><box size="0.3 0.04 0.04"/></geometry>
    </collision>
    <inertial>
      <mass value="0.3"/>
      <inertia ixx="0.001" ixy="0" ixz="0" iyy="0.005" iyz="0" izz="0.005"/>
    </inertial>
  </link>
  <joint name="arm_segment_joint" type="fixed">
    <parent link="arm_column"/>
    <child link="arm_segment"/>
    <origin xyz="0 0 0.18" rpy="0 0 0"/>
  </joint>

  <!-- ============================================================
       GAZEBO PLUGINS
       ============================================================ -->
  <gazebo>
    <plugin filename="gz-sim-diff-drive-system" name="gz::sim::systems::DiffDrive">
      <left_joint>left_wheel_joint</left_joint>
      <right_joint>right_wheel_joint</right_joint>
      <wheel_separation>0.43</wheel_separation>
      <wheel_radius>0.05</wheel_radius>
      <odom_publish_frequency>30</odom_publish_frequency>
      <topic>cmd_vel</topic>
      <odom_topic>odometry</odom_topic>
      <frame_id>odom</frame_id>
      <child_frame_id>base_link</child_frame_id>
    </plugin>

    <plugin filename="gz-sim-joint-state-publisher-system" name="gz::sim::systems::JointStatePublisher">
      <topic>joint_states</topic>
    </plugin>
  </gazebo>

  <!-- Reduce caster friction so the fixed sphere slides without
       resisting rotation. Gazebo per-link friction. -->
  <gazebo reference="caster">
    <mu1>0.05</mu1>
    <mu2>0.05</mu2>
  </gazebo>

</robot>
