<?xml version="1.0"?>
<robot xmlns:xacro="http://www.ros.org/wiki/xacro" name="pos_v2_robot">

  <xacro:property name="pi" value="3.14159265359"/>

  <!-- Base dimensions: small AGV, fits aisles and door easily. -->
  <xacro:property name="base_length" value="0.4"/>
  <xacro:property name="base_width" value="0.4"/>
  <xacro:property name="base_height" value="0.2"/>
  <xacro:property name="base_mass" value="5.0"/>

  <xacro:property name="wheel_radius" value="0.08"/>
  <xacro:property name="wheel_width" value="0.04"/>
  <xacro:property name="wheel_mass" value="0.5"/>
  <xacro:property name="wheel_separation" value="0.44"/>

  <xacro:property name="caster_radius" value="0.04"/>

  <xacro:property name="lidar_radius" value="0.05"/>
  <xacro:property name="lidar_height" value="0.06"/>

  <!--
    base_footprint sits on the ground (z=0). base_link sits on top of
    it, raised by wheel_radius so the wheel centres are at z=0 in the
    base_footprint frame, which is what Nav2 / SLAM expect.
  -->
  <link name="base_footprint"/>

  <joint name="base_footprint_to_base" type="fixed">
    <parent link="base_footprint"/>
    <child link="base_link"/>
    <origin xyz="0 0 ${wheel_radius}" rpy="0 0 0"/>
  </joint>

  <link name="base_link">
    <visual>
      <origin xyz="0 0 ${base_height/2}" rpy="0 0 0"/>
      <geometry>
        <box size="${base_length} ${base_width} ${base_height}"/>
      </geometry>
      <material name="agv_blue">
        <color rgba="0.20 0.35 0.85 1.0"/>
      </material>
    </visual>
    <collision>
      <origin xyz="0 0 ${base_height/2}" rpy="0 0 0"/>
      <geometry>
        <box size="${base_length} ${base_width} ${base_height}"/>
      </geometry>
    </collision>
    <inertial>
      <origin xyz="0 0 ${base_height/2}" rpy="0 0 0"/>
      <mass value="${base_mass}"/>
      <inertia
        ixx="${base_mass*(base_width*base_width + base_height*base_height)/12}"
        ixy="0" ixz="0"
        iyy="${base_mass*(base_length*base_length + base_height*base_height)/12}"
        iyz="0"
        izz="${base_mass*(base_length*base_length + base_width*base_width)/12}"/>
    </inertial>
  </link>

  <xacro:macro name="drive_wheel" params="prefix y_offset">
    <link name="${prefix}_wheel_link">
      <visual>
        <origin xyz="0 0 0" rpy="${pi/2} 0 0"/>
        <geometry>
          <cylinder radius="${wheel_radius}" length="${wheel_width}"/>
        </geometry>
        <material name="wheel_black">
          <color rgba="0.08 0.08 0.08 1.0"/>
        </material>
      </visual>
      <collision>
        <origin xyz="0 0 0" rpy="${pi/2} 0 0"/>
        <geometry>
          <cylinder radius="${wheel_radius}" length="${wheel_width}"/>
        </geometry>
      </collision>
      <inertial>
        <mass value="${wheel_mass}"/>
        <inertia
          ixx="${wheel_mass*(3*wheel_radius*wheel_radius + wheel_width*wheel_width)/12}"
          ixy="0" ixz="0"
          iyy="${wheel_mass*(3*wheel_radius*wheel_radius + wheel_width*wheel_width)/12}"
          iyz="0"
          izz="${wheel_mass*wheel_radius*wheel_radius/2}"/>
      </inertial>
    </link>
    <joint name="${prefix}_wheel_joint" type="continuous">
      <parent link="base_link"/>
      <child link="${prefix}_wheel_link"/>
      <origin xyz="0 ${y_offset} 0" rpy="0 0 0"/>
      <axis xyz="0 1 0"/>
    </joint>
  </xacro:macro>

  <xacro:drive_wheel prefix="left"  y_offset="${ wheel_separation/2}"/>
  <xacro:drive_wheel prefix="right" y_offset="${-wheel_separation/2}"/>

  <!-- Front caster: low-friction ball, keeps the base level. -->
  <link name="caster_link">
    <visual>
      <geometry>
        <sphere radius="${caster_radius}"/>
      </geometry>
      <material name="caster_gray">
        <color rgba="0.30 0.30 0.30 1.0"/>
      </material>
    </visual>
    <collision>
      <geometry>
        <sphere radius="${caster_radius}"/>
      </geometry>
    </collision>
    <inertial>
      <mass value="0.1"/>
      <inertia ixx="0.0001" ixy="0" ixz="0" iyy="0.0001" iyz="0" izz="0.0001"/>
    </inertial>
  </link>

  <joint name="caster_joint" type="fixed">
    <parent link="base_link"/>
    <child link="caster_link"/>
    <origin xyz="${base_length/2 - caster_radius - 0.02} 0 ${-wheel_radius + caster_radius}" rpy="0 0 0"/>
  </joint>

  <gazebo reference="caster_link">
    <mu1>0.001</mu1>
    <mu2>0.001</mu2>
  </gazebo>

  <!-- 2D lidar on top of the base. -->
  <link name="lidar_link">
    <visual>
      <geometry>
        <cylinder radius="${lidar_radius}" length="${lidar_height}"/>
      </geometry>
      <material name="lidar_gray">
        <color rgba="0.15 0.15 0.15 1.0"/>
      </material>
    </visual>
    <collision>
      <geometry>
        <cylinder radius="${lidar_radius}" length="${lidar_height}"/>
      </geometry>
    </collision>
    <inertial>
      <mass value="0.1"/>
      <inertia ixx="0.0001" ixy="0" ixz="0" iyy="0.0001" iyz="0" izz="0.0001"/>
    </inertial>
  </link>

  <joint name="lidar_joint" type="fixed">
    <parent link="base_link"/>
    <child link="lidar_link"/>
    <origin xyz="0 0 ${base_height + lidar_height/2}" rpy="0 0 0"/>
  </joint>

  <!-- IMU mounted in the base. -->
  <link name="imu_link">
    <inertial>
      <mass value="0.01"/>
      <inertia ixx="0.00001" ixy="0" ixz="0" iyy="0.00001" iyz="0" izz="0.00001"/>
    </inertial>
  </link>

  <joint name="imu_joint" type="fixed">
    <parent link="base_link"/>
    <child link="imu_link"/>
    <origin xyz="0 0 ${base_height*0.8}" rpy="0 0 0"/>
  </joint>

  <!-- Gazebo plugins: diff-drive + joint state. -->
  <gazebo>
    <plugin filename="gz-sim-diff-drive-system"
            name="gz::sim::systems::DiffDrive">
      <left_joint>left_wheel_joint</left_joint>
      <right_joint>right_wheel_joint</right_joint>
      <wheel_separation>${wheel_separation}</wheel_separation>
      <wheel_radius>${wheel_radius}</wheel_radius>
      <odom_publish_frequency>50</odom_publish_frequency>
      <max_linear_acceleration>1.0</max_linear_acceleration>
      <max_angular_acceleration>2.0</max_angular_acceleration>
      <topic>cmd_vel</topic>
      <odom_topic>odom</odom_topic>
      <tf_topic>tf</tf_topic>
      <frame_id>odom</frame_id>
      <child_frame_id>base_footprint</child_frame_id>
    </plugin>

    <plugin filename="gz-sim-joint-state-publisher-system"
            name="gz::sim::systems::JointStatePublisher">
      <topic>joint_states</topic>
      <joint_name>left_wheel_joint</joint_name>
      <joint_name>right_wheel_joint</joint_name>
    </plugin>
  </gazebo>

  <!-- Sensors. -->
  <gazebo reference="lidar_link">
    <sensor name="lidar" type="gpu_lidar">
      <topic>scan</topic>
      <gz_frame_id>lidar_link</gz_frame_id>
      <update_rate>10</update_rate>
      <always_on>true</always_on>
      <visualize>true</visualize>
      <lidar>
        <scan>
          <horizontal>
            <samples>360</samples>
            <resolution>1</resolution>
            <min_angle>-${pi}</min_angle>
            <max_angle> ${pi}</max_angle>
          </horizontal>
          <vertical>
            <samples>1</samples>
            <resolution>1</resolution>
            <min_angle>0</min_angle>
            <max_angle>0</max_angle>
          </vertical>
        </scan>
        <range>
          <min>0.12</min>
          <max>12.0</max>
          <resolution>0.01</resolution>
        </range>
        <noise>
          <type>gaussian</type>
          <mean>0.0</mean>
          <stddev>0.01</stddev>
        </noise>
      </lidar>
    </sensor>
  </gazebo>

  <gazebo reference="imu_link">
    <sensor name="imu" type="imu">
      <topic>imu</topic>
      <gz_frame_id>imu_link</gz_frame_id>
      <update_rate>100</update_rate>
      <always_on>true</always_on>
    </sensor>
  </gazebo>

</robot>
